<robot name = "robot">
    <link name="Link0">
        <inertial>
            <origin xyz="0 0 1.25" rpy="0 0 0"/>
            <mass value="2" />
            <inertia ixx="100" ixy="0" ixz="0" iyy="100" iyz="0" izz="100" />
        </inertial>
        <visual>
            <origin xyz="0 0 1.25" rpy="0 0 0"/>
            <geometry>
                <box size="0.6744050801615727 0.5235529253041188 1.0440909874152702" />
            </geometry>
            <material name="Blue">
                <color rgba="0 0 1.0 1.0"/>
            </material>
        </visual>
        <collision>
            <origin xyz="0 0 1.25" rpy="0 0 0"/>
            <geometry>
                <box size="0.6744050801615727 0.5235529253041188 1.0440909874152702" />
            </geometry>
        </collision>
    </link>
    <joint name="Link0_Link1" type="revolute">
       <parent link="Link0"/>
       <child  link="Link1"/>
       <origin rpy="0 0 0" xyz="0 0 1.25" />
     <axis xyz="0 0 1"/>
       <limit effort="0.0" lower="-3.14159" upper="3.14159" velocity="0.0"/>
    </joint>
    <link name="Link1">
        <inertial>
            <origin xyz="1.1463601376711954 0 0" rpy="0 0 0"/>
            <mass value="2" />
            <inertia ixx="100" ixy="0" ixz="0" iyy="100" iyz="0" izz="100" />
        </inertial>
        <visual>
            <origin xyz="1.1463601376711954 0 0" rpy="0 0 0"/>
            <geometry>
                <box size="1.1463601376711954 0.8149627382057472 0.8620922040700858" />
            </geometry>
            <material name="Blue">
                <color rgba="0 0 1.0 1.0"/>
            </material>
        </visual>
        <collision>
            <origin xyz="1.1463601376711954 0 0" rpy="0 0 0"/>
            <geometry>
                <box size="1.1463601376711954 0.8149627382057472 0.8620922040700858" />
            </geometry>
        </collision>
    </link>
    <joint name="Link1_Link2" type="revolute">
       <parent link="Link1"/>
       <child  link="Link2"/>
       <origin rpy="0 0 0" xyz="1.1463601376711954 0 0" />
     <axis xyz="1 0 0"/>
       <limit effort="0.0" lower="-3.14159" upper="3.14159" velocity="0.0"/>
    </joint>
    <link name="Link2">
        <inertial>
            <origin xyz="0.8756742652598635 0 0" rpy="0 0 0"/>
            <mass value="2" />
            <inertia ixx="100" ixy="0" ixz="0" iyy="100" iyz="0" izz="100" />
        </inertial>
        <visual>
            <origin xyz="0.8756742652598635 0 0" rpy="0 0 0"/>
            <geometry>
                <box size="0.8756742652598635 0.8385630050783598 0.9167630536205469" />
            </geometry>
            <material name="Blue">
                <color rgba="0 0 1.0 1.0"/>
            </material>
        </visual>
        <collision>
            <origin xyz="0.8756742652598635 0 0" rpy="0 0 0"/>
            <geometry>
                <box size="0.8756742652598635 0.8385630050783598 0.9167630536205469" />
            </geometry>
        </collision>
    </link>
    <joint name="Link2_Link3" type="revolute">
       <parent link="Link2"/>
       <child  link="Link3"/>
       <origin rpy="0 0 0" xyz="0.8756742652598635 0 0" />
     <axis xyz="0 0 1"/>
       <limit effort="0.0" lower="-3.14159" upper="3.14159" velocity="0.0"/>
    </joint>
    <link name="Link3">
        <inertial>
            <origin xyz="1.0078067320623765 0 0" rpy="0 0 0"/>
            <mass value="2" />
            <inertia ixx="100" ixy="0" ixz="0" iyy="100" iyz="0" izz="100" />
        </inertial>
        <visual>
            <origin xyz="1.0078067320623765 0 0" rpy="0 0 0"/>
            <geometry>
                <box size="1.0078067320623765 1.1566305979245188 1.1585364314099689" />
            </geometry>
            <material name="Green">
                <color rgba="0 1.0 0 1.0"/>
            </material>
        </visual>
        <collision>
            <origin xyz="1.0078067320623765 0 0" rpy="0 0 0"/>
            <geometry>
                <box size="1.0078067320623765 1.1566305979245188 1.1585364314099689" />
            </geometry>
        </collision>
    </link>
    <joint name="Link3_Link4" type="revolute">
       <parent link="Link3"/>
       <child  link="Link4"/>
       <origin rpy="0 0 0" xyz="1.0078067320623765 0 0" />
     <axis xyz="0 1 0"/>
       <limit effort="0.0" lower="-3.14159" upper="3.14159" velocity="0.0"/>
    </joint>
    <link name="Link4">
        <inertial>
            <origin xyz="1.062862474396045 0 0" rpy="0 0 0"/>
            <mass value="2" />
            <inertia ixx="100" ixy="0" ixz="0" iyy="100" iyz="0" izz="100" />
        </inertial>
        <visual>
            <origin xyz="1.062862474396045 0 0" rpy="0 0 0"/>
            <geometry>
                <box size="1.062862474396045 0.8260732929430717 0.8729153047318574" />
            </geometry>
            <material name="Green">
                <color rgba="0 1.0 0 1.0"/>
            </material>
        </visual>
        <collision>
            <origin xyz="1.062862474396045 0 0" rpy="0 0 0"/>
            <geometry>
                <box size="1.062862474396045 0.8260732929430717 0.8729153047318574" />
            </geometry>
        </collision>
    </link>
    <joint name="Link4_Link5" type="revolute">
       <parent link="Link4"/>
       <child  link="Link5"/>
       <origin rpy="0 0 0" xyz="1.062862474396045 0 0" />
     <axis xyz="0 0 1"/>
       <limit effort="0.0" lower="-3.14159" upper="3.14159" velocity="0.0"/>
    </joint>
    <link name="Link5">
        <inertial>
            <origin xyz="0.8812760143213579 0 0" rpy="0 0 0"/>
            <mass value="2" />
            <inertia ixx="100" ixy="0" ixz="0" iyy="100" iyz="0" izz="100" />
        </inertial>
        <visual>
            <origin xyz="0.8812760143213579 0 0" rpy="0 0 0"/>
            <geometry>
                <box size="0.8812760143213579 1.1762219913005327 1.050159279515259" />
            </geometry>
            <material name="Green">
                <color rgba="0 1.0 0 1.0"/>
            </material>
        </visual>
        <collision>
            <origin xyz="0.8812760143213579 0 0" rpy="0 0 0"/>
            <geometry>
                <box size="0.8812760143213579 1.1762219913005327 1.050159279515259" />
            </geometry>
        </collision>
    </link>
</robot>